<mujoco>
    <asset>
        <texture name="grid" type="2d" builtin="checker" rgb1=".1 .2 .3" rgb2=".2 .3 .4" width="300" height="300" mark="none"/>
        <material name="grid" texture="grid" texrepeat="1 1" texuniform="true" reflectance=".2"/>
    </asset>

    <worldbody>
        <light name="light" pos="0 0 1"/>
        <geom name="floor" type="plane" pos="0 0 -.5" size="2 2 .1" material="grid"/>

        <!-- NOTE 锚点1 Site ：作为肌腱（tendon）的固定端点，模拟天花板上的挂钩 -->
        <!-- pos="0 0 .3"：位置在 (0, 0, 0.3)m，即空中某点 -->
        <!-- size=".01"：可视化半径 1cm（仅用于显示，不影响物理） -->
        <site name="anchor" pos="0 0 .3" size=".01"/>

        <camera name="fixed" pos="0 -1.3 .5" xyaxes="1 0 0 0 1 2"/>

        <!-- 支撑柱 -->
        <!-- fromto=".3 0 -.5 .3 0 -.1"：定义圆柱的两个端点 -->
        <!-- 起点：(0.3, 0, -0.5) m（地面）；终点：(0.3, 0, -0.1) m（空中）；高度：-0.1 - (-0.5) = 0.4 m = 40cm -->
        <geom name="pole" type="cylinder" fromto=".3 0 -.5 .3 0 -.1" size=".04"/>

        <!-- 摆锤系统（Bat） -->
        <body name="bat" pos=".3 0 -.1">
            <joint name="swing" type="hinge" damping="1" axis="0 0 1"/>
            <geom name="bat" type="capsule" fromto="0 0 .04 0 -.3 .04" size=".04" rgba="0 0 1 1"/>
        </body>

        <body name="box_and_sphere" pos="0 0 0">
            <joint name="free" type="free"/>
            <geom name="red_box" type="box" size=".1 .1 .1" rgba="1 0 0 1"/>
            <geom name="green_sphere" size=".06" pos=".1 .1 .1" rgba="0 1 0 1"/>

            <!-- NOTE 锚点2 Site ：作为物体上的固定端点，模拟物体上的挂钩 -->
            <!-- pos="-.1 -.1 -.1"：位置 (-10cm, -10cm, -10cm) ，位于方块的左下角（与绿色球体对角），可视化半径 1cm -->
            <site name="hook" pos="-.1 -.1 -.1" size=".01"/>

            <!-- ps 未指定 pos：默认为 (0, 0, 0)（body 中心） -->
            <!-- ps 未指定 size：默认很小，仅用于传感器定位 -->
            <site name="IMU"/>
        </body>
    </worldbody>

    <!-- NOTE 肌腱/绳索 -->
    <tendon>
        <!-- 空间肌腱 -->
        <!-- limited="true"：启用长度限制 -->
        <!-- range="0 0.35"：最小长度：0 m（理论上，实际不会为0），最大长度：0.35 m = 35cm。如果两点距离超过 35cm，肌腱会产生拉力阻止进一步拉伸 -->
        <!-- 可视化线宽 3mm（仅用于渲染） -->
        <spatial name="wire" limited="true" range="0 0.35" width="0.003">
            <!-- 连接 anchor（天花板锚点）和 hook（物体挂钩），形成一条虚拟绳索，将物体悬挂在空中 -->
            <site site="anchor"/>
            <site site="hook"/>
        </spatial>
    </tendon>

    <!-- NOTE 执行器 -->
    <actuator>
        <!-- motor 类型的执行器 -->
        <!-- ! joint="swing"：是指作用于名为 "swing" 的关节（摆锤的旋转关节），而不是关节类型为 "swing"！ -->
        <motor name="my_motor" joint="swing" gear="1"/>
    </actuator>

    <sensor>
        <accelerometer name="accelerometer" site="IMU"/>
    </sensor>
</mujoco>