<mujoco>
    <asset>
        <texture name="grid" type="2d" builtin="checker" rgb1=".1 .2 .3" rgb2=".2 .3 .4" width="300" height="300" mark="none"/>
        <material name="grid" texture="grid" texrepeat="1 1" texuniform="true" reflectance=".2"/>
    </asset>

    <worldbody>
        <light name="light" pos="0 0 1"/>
        <geom name="floor" type="plane" pos="0 0 -.5" size="2 2 .1" material="grid"/>

        <!-- NOTE 锚点1 Site ：作为肌腱（tendon）的固定端点，模拟天花板上的挂钩 -->
        <!-- pos="0 0 .3"：位置在 (0, 0, 0.3)m，即空中某点 -->
        <!-- size=".01"：可视化半径 1cm（仅用于显示，不影响物理） -->
        <site name="anchor" pos="0 0 .3" size=".01"/>

        <!-- step1 固定相机：挂载在 worldbody 下，不动 -->
        <camera name="fixed" pos="0 -1.3 .5" xyaxes="1 0 0 0 1 2"/>

        <!-- NOTE 相机的方向如何定义？？？ -->
        <!-- 方式1：欧拉角，指定绕三个轴依次旋转的角度，默认是内旋XYZ顺序 -->
        <!-- 先绕X转rx度，再绕Y转ry度，再绕Z转rz度（内旋） -->
        <!-- <camera pos="1 0 1" euler="rz ry rx"/> -->
        <!-- 方式2：四元数 -->
        <!-- <camera pos="1 0 1" quat="0.816 0.491 0.158 0.263"/> -->
        <!-- 方式3：xyaxes（最直观！直接告诉 MuJoCo 相机的X轴和Y轴在父坐标系中的方向） -->
        <!-- <camera pos="1 0 1" xyaxes="xx xy xz   yx yy yz"/> -->
        <!-- 方式4：zaxis（指定相机光轴朝向，只需要告诉 MuJoCo 相机看向哪个方向的反方向（即相机Z轴）） -->
        <!-- ! zaxis是相机Z轴方向，相机看向的是-Z！ -->
        <!-- <camera pos="1 0 1" zaxis="1 0 0"/> -->

        <!-- 支撑柱 -->
        <!-- fromto=".3 0 -.5 .3 0 -.1"：定义圆柱的两个端点 -->
        <!-- 起点：(0.3, 0, -0.5) m（地面）；终点：(0.3, 0, -0.1) m（空中）；高度：-0.1 - (-0.5) = 0.4 m = 40cm -->
        <geom name="pole" type="cylinder" fromto=".3 0 -.5 .3 0 -.1" size=".04"/>

        <!-- 摆锤系统（Bat）-->
        <body name="bat" pos=".3 0 -.1">
            <joint name="swing" type="hinge" damping="1" axis="0 0 1"/>
            <geom name="bat" type="capsule" fromto="0 0 .04 0 -.3 .04" size=".04" rgba="0 0 1 1"/>
        </body>

        <body name="box_and_sphere" pos="0 0 0">
            <joint name="free" type="free"/>
            <geom name="red_box" type="box" size=".1 .1 .1" rgba="1 0 0 1"/>
            <geom name="green_sphere" size=".06" pos=".1 .1 .1" rgba="0 1 0 1"/>

            <!-- step2 跟随相机：挂载在 body 下，可跟随机器人头部运动 -->
            <body name="head">
                <camera name="head_cam" pos="0.05 0 0" euler="0 0 0" fovy="90"/>
            </body>

            <!-- NOTE 锚点2 Site ：作为物体上的固定端点，模拟物体上的挂钩 -->
            <!-- pos="-.1 -.1 -.1"：位置 (-10cm, -10cm, -10cm) ，位于方块的左下角（与绿色球体对角），可视化半径 1cm -->
            <site name="hook" pos="-.1 -.1 -.1" size=".01"/>

            <!-- ps 未指定 pos：默认为 (0, 0, 0)（body 中心） -->
            <!-- ps 未指定 size：默认很小，仅用于传感器定位 -->
            <site name="IMU"/>
        </body>
    </worldbody>

    <!-- NOTE 肌腱/绳索 -->
    <tendon>
        <!-- 空间肌腱 -->
        <!-- limited="true"：启用长度限制 -->
        <!-- range="0 0.35"：最小长度：0 m（理论上，实际不会为0），最大长度：0.35 m = 35cm。如果两点距离超过 35cm，肌腱会产生拉力阻止进一步拉伸 -->
        <!-- 可视化线宽 3mm（仅用于渲染） -->
        <spatial name="wire" limited="true" range="0 0.35" width="0.003">
            <!-- 连接 anchor（天花板锚点）和 hook（物体挂钩），形成一条虚拟绳索，将物体悬挂在空中 -->
            <site site="anchor"/>
            <site site="hook"/>
        </spatial>
    </tendon>

    <!-- NOTE 执行器 -->
    <actuator>
        <!-- motor 类型的执行器 -->
        <!-- ! joint="swing"：是指作用于名为 "swing" 的关节（摆锤的旋转关节），而不是关节类型为 "swing"！ -->
        <!-- gear="1"：传动比为 1 ：控制信号 ctrl 直接映射到力或力矩：τ = ctrl × gear = ctrl × 1，例如：如果 ctrl = 0.5，则施加 0.5 N·m 的力矩 -->
        <motor name="my_motor" joint="swing" gear="1"/>
    </actuator>

    <!-- NOTE 传感器 -->
    <sensor>
        <!-- 加速度计（accelerometer），输出 3 维加速度向量 (ax, ay, az)，单位：m/s² -->
        <accelerometer name="accelerometer" site="IMU"/>
    </sensor>
</mujoco>